<?xml version="1.0" encoding="UTF-8" ?>
<testsuites errors="0"
            failures="1"
            tests="1">

  <testsuite name="unittest-failure"
    errors="0" failures="1" hostname="" id="" package="unittest-failure" skipped="0"
    tests="1" time="0.001000" timestamp="Tue, 20 Sep 2016 22:54:27 GMT">
  
    <testcase name="demoTest" time="0.001000" assertions="0"><failure message="AssertionError: 1 == 0 - expected &quot;0&quot; but got: &quot;1&quot;">    at Object.module.exports.demoTest (/Users/mikhaildzarasov/Desktop/newnghtwatch/nightwatch/test/asynchookstests/unittest-failure/unittest-failure.js:5:12)
    at Object.&lt;anonymous&gt; (/Users/mikhaildzarasov/Desktop/newnghtwatch/nightwatch/lib/util/utils.js:35:8)
    at Module.callAsync (/Users/mikhaildzarasov/Desktop/newnghtwatch/nightwatch/lib/runner/module.js:75:18)
    at /Users/mikhaildzarasov/Desktop/newnghtwatch/nightwatch/lib/runner/testcase.js:77:43</failure>
    </testcase>
  
  
  </testsuite>
</testsuites>
